2021-04-30 15:47:20,245 INFO: Microblog startup [in C:\Users\Piggy\PycharmProjects\newproject\CWA-EA\app\__init__.py:74]
2021-04-30 15:47:24,341 ERROR: Exception on / [GET] [in C:\Users\Piggy\PycharmProjects\CWA-EA\venv\lib\site-packages\flask\app.py:1761]
Traceback (most recent call last):
  File "C:\Users\Piggy\PycharmProjects\CWA-EA\venv\lib\site-packages\sqlalchemy\orm\relationships.py", line 2082, in _determine_joins
    consider_as_foreign_keys=consider_as_foreign_keys
  File "<string>", line 2, in join_condition
  File "C:\Users\Piggy\PycharmProjects\CWA-EA\venv\lib\site-packages\sqlalchemy\sql\selectable.py", line 979, in _join_condition
    (a.description, b.description, hint))
sqlalchemy.exc.NoForeignKeysError: Can't find any foreign key relationships between 'newtopic' and 'reply'.

During handling of the above exception, another exception occurred:

Traceback (most recent call last):
  File "C:\Users\Piggy\PycharmProjects\CWA-EA\venv\lib\site-packages\flask\app.py", line 2292, in wsgi_app
    response = self.full_dispatch_request()
  File "C:\Users\Piggy\PycharmProjects\CWA-EA\venv\lib\site-packages\flask\app.py", line 1815, in full_dispatch_request
    rv = self.handle_user_exception(e)
  File "C:\Users\Piggy\PycharmProjects\CWA-EA\venv\lib\site-packages\flask\app.py", line 1718, in handle_user_exception
    reraise(exc_type, exc_value, tb)
  File "C:\Users\Piggy\PycharmProjects\CWA-EA\venv\lib\site-packages\flask\_compat.py", line 35, in reraise
    raise value
  File "C:\Users\Piggy\PycharmProjects\CWA-EA\venv\lib\site-packages\flask\app.py", line 1811, in full_dispatch_request
    rv = self.preprocess_request()
  File "C:\Users\Piggy\PycharmProjects\CWA-EA\venv\lib\site-packages\flask\app.py", line 2087, in preprocess_request
    rv = func()
  File "C:\Users\Piggy\PycharmProjects\newproject\CWA-EA\app\main\routes.py", line 13, in before_request
    if current_user.is_authenticated:
  File "C:\Users\Piggy\PycharmProjects\CWA-EA\venv\lib\site-packages\werkzeug\local.py", line 347, in __getattr__
    return getattr(self._get_current_object(), name)
  File "C:\Users\Piggy\PycharmProjects\CWA-EA\venv\lib\site-packages\werkzeug\local.py", line 306, in _get_current_object
    return self.__local()
  File "C:\Users\Piggy\PycharmProjects\CWA-EA\venv\lib\site-packages\flask_login\utils.py", line 26, in <lambda>
    current_user = LocalProxy(lambda: _get_user())
  File "C:\Users\Piggy\PycharmProjects\CWA-EA\venv\lib\site-packages\flask_login\utils.py", line 335, in _get_user
    current_app.login_manager._load_user()
  File "C:\Users\Piggy\PycharmProjects\CWA-EA\venv\lib\site-packages\flask_login\login_manager.py", line 359, in _load_user
    return self.reload_user()
  File "C:\Users\Piggy\PycharmProjects\CWA-EA\venv\lib\site-packages\flask_login\login_manager.py", line 321, in reload_user
    user = self.user_callback(user_id)
  File "C:\Users\Piggy\PycharmProjects\newproject\CWA-EA\app\models.py", line 105, in load_user
    return User.query.get(int(id))
  File "C:\Users\Piggy\PycharmProjects\CWA-EA\venv\lib\site-packages\flask_sqlalchemy\__init__.py", line 512, in __get__
    mapper = orm.class_mapper(type)
  File "C:\Users\Piggy\PycharmProjects\CWA-EA\venv\lib\site-packages\sqlalchemy\orm\base.py", line 421, in class_mapper
    mapper = _inspect_mapped_class(class_, configure=configure)
  File "C:\Users\Piggy\PycharmProjects\CWA-EA\venv\lib\site-packages\sqlalchemy\orm\base.py", line 400, in _inspect_mapped_class
    mapper._configure_all()
  File "C:\Users\Piggy\PycharmProjects\CWA-EA\venv\lib\site-packages\sqlalchemy\orm\mapper.py", line 1272, in _configure_all
    configure_mappers()
  File "C:\Users\Piggy\PycharmProjects\CWA-EA\venv\lib\site-packages\sqlalchemy\orm\mapper.py", line 3029, in configure_mappers
    mapper._post_configure_properties()
  File "C:\Users\Piggy\PycharmProjects\CWA-EA\venv\lib\site-packages\sqlalchemy\orm\mapper.py", line 1828, in _post_configure_properties
    prop.init()
  File "C:\Users\Piggy\PycharmProjects\CWA-EA\venv\lib\site-packages\sqlalchemy\orm\interfaces.py", line 184, in init
    self.do_init()
  File "C:\Users\Piggy\PycharmProjects\CWA-EA\venv\lib\site-packages\sqlalchemy\orm\relationships.py", line 1656, in do_init
    self._setup_join_conditions()
  File "C:\Users\Piggy\PycharmProjects\CWA-EA\venv\lib\site-packages\sqlalchemy\orm\relationships.py", line 1731, in _setup_join_conditions
    can_be_synced_fn=self._columns_are_mapped
  File "C:\Users\Piggy\PycharmProjects\CWA-EA\venv\lib\site-packages\sqlalchemy\orm\relationships.py", line 1998, in __init__
    self._determine_joins()
  File "C:\Users\Piggy\PycharmProjects\CWA-EA\venv\lib\site-packages\sqlalchemy\orm\relationships.py", line 2103, in _determine_joins
    "specify a 'primaryjoin' expression." % self.prop)
sqlalchemy.exc.NoForeignKeysError: Could not determine join condition between parent/child tables on relationship Newtopic.replys - there are no foreign keys linking these tables.  Ensure that referencing columns are associated with a ForeignKey or ForeignKeyConstraint, or specify a 'primaryjoin' expression.
2021-04-30 15:59:19,553 INFO: Microblog startup [in C:\Users\Piggy\PycharmProjects\newproject\CWA-EA\app\__init__.py:74]
