<<<<<<< HEAD
2021-04-30 01:49:35,807 ERROR: Exception on /user/test123 [GET] [in /Users/pearly/PycharmProjects/HKGolden/venv/lib/python3.7/site-packages/flask/app.py:1761]
Traceback (most recent call last):
  File "/Users/pearly/PycharmProjects/HKGolden/venv/lib/python3.7/site-packages/flask/app.py", line 2292, in wsgi_app
    response = self.full_dispatch_request()
  File "/Users/pearly/PycharmProjects/HKGolden/venv/lib/python3.7/site-packages/flask/app.py", line 1815, in full_dispatch_request
    rv = self.handle_user_exception(e)
  File "/Users/pearly/PycharmProjects/HKGolden/venv/lib/python3.7/site-packages/flask/app.py", line 1718, in handle_user_exception
    reraise(exc_type, exc_value, tb)
  File "/Users/pearly/PycharmProjects/HKGolden/venv/lib/python3.7/site-packages/flask/_compat.py", line 35, in reraise
    raise value
  File "/Users/pearly/PycharmProjects/HKGolden/venv/lib/python3.7/site-packages/flask/app.py", line 1813, in full_dispatch_request
    rv = self.dispatch_request()
  File "/Users/pearly/PycharmProjects/HKGolden/venv/lib/python3.7/site-packages/flask/app.py", line 1799, in dispatch_request
    return self.view_functions[rule.endpoint](**req.view_args)
  File "/Users/pearly/PycharmProjects/HKGolden/venv/lib/python3.7/site-packages/flask_login/utils.py", line 261, in decorated_view
    return func(*args, **kwargs)
  File "/Users/pearly/PycharmProjects/HKGolden/app/main/routes.py", line 74, in user
    next_url=next_url, prev_url=prev_url)
  File "/Users/pearly/PycharmProjects/HKGolden/venv/lib/python3.7/site-packages/flask/templating.py", line 135, in render_template
    context, ctx.app)
  File "/Users/pearly/PycharmProjects/HKGolden/venv/lib/python3.7/site-packages/flask/templating.py", line 117, in _render
    rv = template.render(context)
  File "/Users/pearly/PycharmProjects/HKGolden/venv/lib/python3.7/site-packages/jinja2/asyncsupport.py", line 76, in render
    return original_render(self, *args, **kwargs)
  File "/Users/pearly/PycharmProjects/HKGolden/venv/lib/python3.7/site-packages/jinja2/environment.py", line 1008, in render
    return self.environment.handle_exception(exc_info, True)
  File "/Users/pearly/PycharmProjects/HKGolden/venv/lib/python3.7/site-packages/jinja2/environment.py", line 780, in handle_exception
    reraise(exc_type, exc_value, tb)
  File "/Users/pearly/PycharmProjects/HKGolden/venv/lib/python3.7/site-packages/jinja2/_compat.py", line 37, in reraise
    raise value.with_traceback(tb)
  File "/Users/pearly/PycharmProjects/HKGolden/app/templates/user.html", line 1, in top-level template code
    {% extends "base.html" %}
  File "/Users/pearly/PycharmProjects/HKGolden/app/templates/base.html", line 1, in top-level template code
    {% extends 'bootstrap/base.html' %}
  File "/Users/pearly/PycharmProjects/HKGolden/venv/lib/python3.7/site-packages/flask_bootstrap/templates/bootstrap/base.html", line 1, in top-level template code
    {% block doc -%}
  File "/Users/pearly/PycharmProjects/HKGolden/venv/lib/python3.7/site-packages/flask_bootstrap/templates/bootstrap/base.html", line 4, in block "doc"
    {%- block html %}
  File "/Users/pearly/PycharmProjects/HKGolden/venv/lib/python3.7/site-packages/flask_bootstrap/templates/bootstrap/base.html", line 20, in block "html"
    {% block body -%}
  File "/Users/pearly/PycharmProjects/HKGolden/venv/lib/python3.7/site-packages/flask_bootstrap/templates/bootstrap/base.html", line 23, in block "body"
    {% block content -%}
  File "/Users/pearly/PycharmProjects/HKGolden/app/templates/base.html", line 187, in block "content"
    {% block current_app_content %}{% endblock %}
  File "/Users/pearly/PycharmProjects/HKGolden/app/templates/user.html", line 14, in block "current_app_content"
    <p>{{ _('%(count)d blocked', count=user.blocker.count()) }}</p>
  File "/Users/pearly/PycharmProjects/HKGolden/venv/lib/python3.7/site-packages/jinja2/environment.py", line 430, in getattr
    return getattr(obj, attribute)
jinja2.exceptions.UndefinedError: 'app.models.User object' has no attribute 'blocker'
2021-04-30 01:51:58,249 INFO: Microblog startup [in /Users/pearly/PycharmProjects/HKGolden/app/__init__.py:74]
2021-04-30 01:52:00,030 ERROR: Exception on /user/test123 [GET] [in /Users/pearly/PycharmProjects/HKGolden/venv/lib/python3.7/site-packages/flask/app.py:1761]
Traceback (most recent call last):
  File "/Users/pearly/PycharmProjects/HKGolden/venv/lib/python3.7/site-packages/flask/app.py", line 2292, in wsgi_app
    response = self.full_dispatch_request()
  File "/Users/pearly/PycharmProjects/HKGolden/venv/lib/python3.7/site-packages/flask/app.py", line 1815, in full_dispatch_request
    rv = self.handle_user_exception(e)
  File "/Users/pearly/PycharmProjects/HKGolden/venv/lib/python3.7/site-packages/flask/app.py", line 1718, in handle_user_exception
    reraise(exc_type, exc_value, tb)
  File "/Users/pearly/PycharmProjects/HKGolden/venv/lib/python3.7/site-packages/flask/_compat.py", line 35, in reraise
    raise value
  File "/Users/pearly/PycharmProjects/HKGolden/venv/lib/python3.7/site-packages/flask/app.py", line 1813, in full_dispatch_request
    rv = self.dispatch_request()
  File "/Users/pearly/PycharmProjects/HKGolden/venv/lib/python3.7/site-packages/flask/app.py", line 1799, in dispatch_request
    return self.view_functions[rule.endpoint](**req.view_args)
  File "/Users/pearly/PycharmProjects/HKGolden/venv/lib/python3.7/site-packages/flask_login/utils.py", line 261, in decorated_view
    return func(*args, **kwargs)
  File "/Users/pearly/PycharmProjects/HKGolden/app/main/routes.py", line 74, in user
    next_url=next_url, prev_url=prev_url)
  File "/Users/pearly/PycharmProjects/HKGolden/venv/lib/python3.7/site-packages/flask/templating.py", line 135, in render_template
    context, ctx.app)
  File "/Users/pearly/PycharmProjects/HKGolden/venv/lib/python3.7/site-packages/flask/templating.py", line 117, in _render
    rv = template.render(context)
  File "/Users/pearly/PycharmProjects/HKGolden/venv/lib/python3.7/site-packages/jinja2/asyncsupport.py", line 76, in render
    return original_render(self, *args, **kwargs)
  File "/Users/pearly/PycharmProjects/HKGolden/venv/lib/python3.7/site-packages/jinja2/environment.py", line 1008, in render
    return self.environment.handle_exception(exc_info, True)
  File "/Users/pearly/PycharmProjects/HKGolden/venv/lib/python3.7/site-packages/jinja2/environment.py", line 780, in handle_exception
    reraise(exc_type, exc_value, tb)
  File "/Users/pearly/PycharmProjects/HKGolden/venv/lib/python3.7/site-packages/jinja2/_compat.py", line 37, in reraise
    raise value.with_traceback(tb)
  File "/Users/pearly/PycharmProjects/HKGolden/app/templates/user.html", line 1, in top-level template code
    {% extends "base.html" %}
  File "/Users/pearly/PycharmProjects/HKGolden/app/templates/base.html", line 1, in top-level template code
    {% extends 'bootstrap/base.html' %}
  File "/Users/pearly/PycharmProjects/HKGolden/venv/lib/python3.7/site-packages/flask_bootstrap/templates/bootstrap/base.html", line 1, in top-level template code
    {% block doc -%}
  File "/Users/pearly/PycharmProjects/HKGolden/venv/lib/python3.7/site-packages/flask_bootstrap/templates/bootstrap/base.html", line 4, in block "doc"
    {%- block html %}
  File "/Users/pearly/PycharmProjects/HKGolden/venv/lib/python3.7/site-packages/flask_bootstrap/templates/bootstrap/base.html", line 20, in block "html"
    {% block body -%}
  File "/Users/pearly/PycharmProjects/HKGolden/venv/lib/python3.7/site-packages/flask_bootstrap/templates/bootstrap/base.html", line 23, in block "body"
    {% block content -%}
  File "/Users/pearly/PycharmProjects/HKGolden/app/templates/base.html", line 187, in block "content"
    {% block current_app_content %}{% endblock %}
  File "/Users/pearly/PycharmProjects/HKGolden/app/templates/user.html", line 14, in block "current_app_content"
    <p>{{ _('%(count)d blocked', count=user.blocker.count()) }}</p>
  File "/Users/pearly/PycharmProjects/HKGolden/venv/lib/python3.7/site-packages/jinja2/environment.py", line 430, in getattr
    return getattr(obj, attribute)
jinja2.exceptions.UndefinedError: 'app.models.User object' has no attribute 'blocker'
2021-04-30 01:53:54,282 INFO: Microblog startup [in /Users/pearly/PycharmProjects/HKGolden/app/__init__.py:74]
=======
2021-04-28 01:55:04,167 ERROR: Exception on /new_topic [POST] [in C:\Users\Piggy\PycharmProjects\CWA-EA\venv\lib\site-packages\flask\app.py:1761]
Traceback (most recent call last):
  File "C:\Users\Piggy\PycharmProjects\CWA-EA\venv\lib\site-packages\flask\app.py", line 2292, in wsgi_app
    response = self.full_dispatch_request()
  File "C:\Users\Piggy\PycharmProjects\CWA-EA\venv\lib\site-packages\flask\app.py", line 1815, in full_dispatch_request
    rv = self.handle_user_exception(e)
  File "C:\Users\Piggy\PycharmProjects\CWA-EA\venv\lib\site-packages\flask\app.py", line 1718, in handle_user_exception
    reraise(exc_type, exc_value, tb)
  File "C:\Users\Piggy\PycharmProjects\CWA-EA\venv\lib\site-packages\flask\_compat.py", line 35, in reraise
    raise value
  File "C:\Users\Piggy\PycharmProjects\CWA-EA\venv\lib\site-packages\flask\app.py", line 1813, in full_dispatch_request
    rv = self.dispatch_request()
  File "C:\Users\Piggy\PycharmProjects\CWA-EA\venv\lib\site-packages\flask\app.py", line 1799, in dispatch_request
    return self.view_functions[rule.endpoint](**req.view_args)
  File "C:\Users\Piggy\PycharmProjects\CWA-EA\app\main\routes.py", line 98, in new_topic
    topic=form.topic.data, post=form.post.data, tag=form.tag.data)
TypeError: __init__() missing 1 required positional argument: 'timestamp'
2021-04-28 01:55:46,470 INFO: Microblog startup [in C:\Users\Piggy\PycharmProjects\CWA-EA\app\__init__.py:74]
2021-04-28 02:22:42,942 INFO: Microblog startup [in C:\Users\Piggy\PycharmProjects\CWA-EA\app\__init__.py:74]
2021-04-28 02:22:44,461 INFO: Microblog startup [in C:\Users\Piggy\PycharmProjects\CWA-EA\app\__init__.py:74]
2021-04-28 02:24:58,322 ERROR: Exception on /new_topic [POST] [in C:\Users\Piggy\PycharmProjects\CWA-EA\venv\lib\site-packages\flask\app.py:1761]
Traceback (most recent call last):
  File "C:\Users\Piggy\PycharmProjects\CWA-EA\venv\lib\site-packages\flask\app.py", line 2292, in wsgi_app
    response = self.full_dispatch_request()
  File "C:\Users\Piggy\PycharmProjects\CWA-EA\venv\lib\site-packages\flask\app.py", line 1815, in full_dispatch_request
    rv = self.handle_user_exception(e)
  File "C:\Users\Piggy\PycharmProjects\CWA-EA\venv\lib\site-packages\flask\app.py", line 1718, in handle_user_exception
    reraise(exc_type, exc_value, tb)
  File "C:\Users\Piggy\PycharmProjects\CWA-EA\venv\lib\site-packages\flask\_compat.py", line 35, in reraise
    raise value
  File "C:\Users\Piggy\PycharmProjects\CWA-EA\venv\lib\site-packages\flask\app.py", line 1813, in full_dispatch_request
    rv = self.dispatch_request()
  File "C:\Users\Piggy\PycharmProjects\CWA-EA\venv\lib\site-packages\flask\app.py", line 1799, in dispatch_request
    return self.view_functions[rule.endpoint](**req.view_args)
  File "C:\Users\Piggy\PycharmProjects\CWA-EA\app\main\routes.py", line 99, in new_topic
    user_id=form.user_id.data)
TypeError: __init__() missing 1 required positional argument: 'timestamp'
2021-04-28 15:44:56,512 INFO: Microblog startup [in C:\Users\Piggy\PycharmProjects\CWA-EA\app\__init__.py:74]
2021-04-28 15:45:24,690 ERROR: Exception on /new_topic [POST] [in C:\Users\Piggy\PycharmProjects\CWA-EA\venv\lib\site-packages\flask\app.py:1761]
Traceback (most recent call last):
  File "C:\Users\Piggy\PycharmProjects\CWA-EA\venv\lib\site-packages\flask\app.py", line 2292, in wsgi_app
    response = self.full_dispatch_request()
  File "C:\Users\Piggy\PycharmProjects\CWA-EA\venv\lib\site-packages\flask\app.py", line 1815, in full_dispatch_request
    rv = self.handle_user_exception(e)
  File "C:\Users\Piggy\PycharmProjects\CWA-EA\venv\lib\site-packages\flask\app.py", line 1718, in handle_user_exception
    reraise(exc_type, exc_value, tb)
  File "C:\Users\Piggy\PycharmProjects\CWA-EA\venv\lib\site-packages\flask\_compat.py", line 35, in reraise
    raise value
  File "C:\Users\Piggy\PycharmProjects\CWA-EA\venv\lib\site-packages\flask\app.py", line 1813, in full_dispatch_request
    rv = self.dispatch_request()
  File "C:\Users\Piggy\PycharmProjects\CWA-EA\venv\lib\site-packages\flask\app.py", line 1799, in dispatch_request
    return self.view_functions[rule.endpoint](**req.view_args)
  File "C:\Users\Piggy\PycharmProjects\CWA-EA\app\main\routes.py", line 99, in new_topic
    user_id=form.user_id.data)
TypeError: __init__() missing 1 required positional argument: 'timestamp'
2021-04-28 16:10:01,742 INFO: Microblog startup [in C:\Users\Piggy\PycharmProjects\CWA-EA\app\__init__.py:74]
2021-04-28 16:10:07,362 ERROR: Exception on /new_topic [POST] [in C:\Users\Piggy\PycharmProjects\CWA-EA\venv\lib\site-packages\flask\app.py:1761]
Traceback (most recent call last):
  File "C:\Users\Piggy\PycharmProjects\CWA-EA\venv\lib\site-packages\flask\app.py", line 2292, in wsgi_app
    response = self.full_dispatch_request()
  File "C:\Users\Piggy\PycharmProjects\CWA-EA\venv\lib\site-packages\flask\app.py", line 1815, in full_dispatch_request
    rv = self.handle_user_exception(e)
  File "C:\Users\Piggy\PycharmProjects\CWA-EA\venv\lib\site-packages\flask\app.py", line 1718, in handle_user_exception
    reraise(exc_type, exc_value, tb)
  File "C:\Users\Piggy\PycharmProjects\CWA-EA\venv\lib\site-packages\flask\_compat.py", line 35, in reraise
    raise value
  File "C:\Users\Piggy\PycharmProjects\CWA-EA\venv\lib\site-packages\flask\app.py", line 1813, in full_dispatch_request
    rv = self.dispatch_request()
  File "C:\Users\Piggy\PycharmProjects\CWA-EA\venv\lib\site-packages\flask\app.py", line 1799, in dispatch_request
    return self.view_functions[rule.endpoint](**req.view_args)
  File "C:\Users\Piggy\PycharmProjects\CWA-EA\app\main\routes.py", line 99, in new_topic
    user_id=form.user_id.data, timestamp=form.timestamp.data)
AttributeError: 'TopicForm' object has no attribute 'timestamp'
2021-04-28 16:18:18,861 INFO: Microblog startup [in C:\Users\Piggy\PycharmProjects\CWA-EA\app\__init__.py:74]
2021-04-28 16:18:33,943 INFO: Microblog startup [in C:\Users\Piggy\PycharmProjects\CWA-EA\app\__init__.py:74]
2021-04-28 16:18:39,627 ERROR: Exception on /new_topic [POST] [in C:\Users\Piggy\PycharmProjects\CWA-EA\venv\lib\site-packages\flask\app.py:1761]
Traceback (most recent call last):
  File "C:\Users\Piggy\PycharmProjects\CWA-EA\venv\lib\site-packages\flask\app.py", line 2292, in wsgi_app
    response = self.full_dispatch_request()
  File "C:\Users\Piggy\PycharmProjects\CWA-EA\venv\lib\site-packages\flask\app.py", line 1815, in full_dispatch_request
    rv = self.handle_user_exception(e)
  File "C:\Users\Piggy\PycharmProjects\CWA-EA\venv\lib\site-packages\flask\app.py", line 1718, in handle_user_exception
    reraise(exc_type, exc_value, tb)
  File "C:\Users\Piggy\PycharmProjects\CWA-EA\venv\lib\site-packages\flask\_compat.py", line 35, in reraise
    raise value
  File "C:\Users\Piggy\PycharmProjects\CWA-EA\venv\lib\site-packages\flask\app.py", line 1813, in full_dispatch_request
    rv = self.dispatch_request()
  File "C:\Users\Piggy\PycharmProjects\CWA-EA\venv\lib\site-packages\flask\app.py", line 1799, in dispatch_request
    return self.view_functions[rule.endpoint](**req.view_args)
  File "C:\Users\Piggy\PycharmProjects\CWA-EA\app\main\routes.py", line 99, in new_topic
    user_id=form.user_id.data)
TypeError: __init__() missing 1 required positional argument: 'timestamp'
2021-04-28 16:35:59,771 INFO: Microblog startup [in C:\Users\Piggy\PycharmProjects\CWA-EA\app\__init__.py:74]
2021-04-28 16:36:04,031 ERROR: Exception on /new_topic [POST] [in C:\Users\Piggy\PycharmProjects\CWA-EA\venv\lib\site-packages\flask\app.py:1761]
Traceback (most recent call last):
  File "C:\Users\Piggy\PycharmProjects\CWA-EA\venv\lib\site-packages\flask\app.py", line 2292, in wsgi_app
    response = self.full_dispatch_request()
  File "C:\Users\Piggy\PycharmProjects\CWA-EA\venv\lib\site-packages\flask\app.py", line 1815, in full_dispatch_request
    rv = self.handle_user_exception(e)
  File "C:\Users\Piggy\PycharmProjects\CWA-EA\venv\lib\site-packages\flask\app.py", line 1718, in handle_user_exception
    reraise(exc_type, exc_value, tb)
  File "C:\Users\Piggy\PycharmProjects\CWA-EA\venv\lib\site-packages\flask\_compat.py", line 35, in reraise
    raise value
  File "C:\Users\Piggy\PycharmProjects\CWA-EA\venv\lib\site-packages\flask\app.py", line 1813, in full_dispatch_request
    rv = self.dispatch_request()
  File "C:\Users\Piggy\PycharmProjects\CWA-EA\venv\lib\site-packages\flask\app.py", line 1799, in dispatch_request
    return self.view_functions[rule.endpoint](**req.view_args)
  File "C:\Users\Piggy\PycharmProjects\CWA-EA\app\main\routes.py", line 99, in new_topic
    user_id=form.user_id.data)
TypeError: __init__() missing 1 required positional argument: 'timestamp'
2021-04-28 16:36:09,051 ERROR: Exception on /new_topic [POST] [in C:\Users\Piggy\PycharmProjects\CWA-EA\venv\lib\site-packages\flask\app.py:1761]
Traceback (most recent call last):
  File "C:\Users\Piggy\PycharmProjects\CWA-EA\venv\lib\site-packages\flask\app.py", line 2292, in wsgi_app
    response = self.full_dispatch_request()
  File "C:\Users\Piggy\PycharmProjects\CWA-EA\venv\lib\site-packages\flask\app.py", line 1815, in full_dispatch_request
    rv = self.handle_user_exception(e)
  File "C:\Users\Piggy\PycharmProjects\CWA-EA\venv\lib\site-packages\flask\app.py", line 1718, in handle_user_exception
    reraise(exc_type, exc_value, tb)
  File "C:\Users\Piggy\PycharmProjects\CWA-EA\venv\lib\site-packages\flask\_compat.py", line 35, in reraise
    raise value
  File "C:\Users\Piggy\PycharmProjects\CWA-EA\venv\lib\site-packages\flask\app.py", line 1813, in full_dispatch_request
    rv = self.dispatch_request()
  File "C:\Users\Piggy\PycharmProjects\CWA-EA\venv\lib\site-packages\flask\app.py", line 1799, in dispatch_request
    return self.view_functions[rule.endpoint](**req.view_args)
  File "C:\Users\Piggy\PycharmProjects\CWA-EA\app\main\routes.py", line 99, in new_topic
    user_id=form.user_id.data)
TypeError: __init__() missing 1 required positional argument: 'timestamp'
>>>>>>> 593fe042620a6dc5d1acc85f55bf58d726937e45
