2021-04-28 16:37:01,625 INFO: Microblog startup [in C:\Users\Piggy\PycharmProjects\CWA-EA\app\__init__.py:74]
2021-04-28 16:37:10,114 ERROR: Exception on /new_topic [POST] [in C:\Users\Piggy\PycharmProjects\CWA-EA\venv\lib\site-packages\flask\app.py:1761]
Traceback (most recent call last):
  File "C:\Users\Piggy\PycharmProjects\CWA-EA\venv\lib\site-packages\flask\app.py", line 2292, in wsgi_app
    response = self.full_dispatch_request()
  File "C:\Users\Piggy\PycharmProjects\CWA-EA\venv\lib\site-packages\flask\app.py", line 1815, in full_dispatch_request
    rv = self.handle_user_exception(e)
  File "C:\Users\Piggy\PycharmProjects\CWA-EA\venv\lib\site-packages\flask\app.py", line 1718, in handle_user_exception
    reraise(exc_type, exc_value, tb)
  File "C:\Users\Piggy\PycharmProjects\CWA-EA\venv\lib\site-packages\flask\_compat.py", line 35, in reraise
    raise value
  File "C:\Users\Piggy\PycharmProjects\CWA-EA\venv\lib\site-packages\flask\app.py", line 1813, in full_dispatch_request
    rv = self.dispatch_request()
  File "C:\Users\Piggy\PycharmProjects\CWA-EA\venv\lib\site-packages\flask\app.py", line 1799, in dispatch_request
    return self.view_functions[rule.endpoint](**req.view_args)
  File "C:\Users\Piggy\PycharmProjects\CWA-EA\app\main\routes.py", line 99, in new_topic
    user_id=form.user_id.data)
TypeError: __init__() missing 1 required positional argument: 'timestamp'
2021-04-28 17:14:27,442 INFO: Microblog startup [in C:\Users\Piggy\PycharmProjects\CWA-EA\app\__init__.py:74]
2021-04-28 17:14:30,973 ERROR: Exception on /new_topic [POST] [in C:\Users\Piggy\PycharmProjects\CWA-EA\venv\lib\site-packages\flask\app.py:1761]
Traceback (most recent call last):
  File "C:\Users\Piggy\PycharmProjects\CWA-EA\venv\lib\site-packages\sqlalchemy\engine\base.py", line 1193, in _execute_context
    context)
  File "C:\Users\Piggy\PycharmProjects\CWA-EA\venv\lib\site-packages\sqlalchemy\engine\default.py", line 508, in do_execute
    cursor.execute(statement, parameters)
sqlite3.IntegrityError: datatype mismatch

The above exception was the direct cause of the following exception:

Traceback (most recent call last):
  File "C:\Users\Piggy\PycharmProjects\CWA-EA\venv\lib\site-packages\flask\app.py", line 2292, in wsgi_app
    response = self.full_dispatch_request()
  File "C:\Users\Piggy\PycharmProjects\CWA-EA\venv\lib\site-packages\flask\app.py", line 1815, in full_dispatch_request
    rv = self.handle_user_exception(e)
  File "C:\Users\Piggy\PycharmProjects\CWA-EA\venv\lib\site-packages\flask\app.py", line 1718, in handle_user_exception
    reraise(exc_type, exc_value, tb)
  File "C:\Users\Piggy\PycharmProjects\CWA-EA\venv\lib\site-packages\flask\_compat.py", line 35, in reraise
    raise value
  File "C:\Users\Piggy\PycharmProjects\CWA-EA\venv\lib\site-packages\flask\app.py", line 1813, in full_dispatch_request
    rv = self.dispatch_request()
  File "C:\Users\Piggy\PycharmProjects\CWA-EA\venv\lib\site-packages\flask\app.py", line 1799, in dispatch_request
    return self.view_functions[rule.endpoint](**req.view_args)
  File "C:\Users\Piggy\PycharmProjects\CWA-EA\app\main\routes.py", line 101, in new_topic
    db.session.commit()
  File "C:\Users\Piggy\PycharmProjects\CWA-EA\venv\lib\site-packages\sqlalchemy\orm\scoping.py", line 153, in do
    return getattr(self.registry(), name)(*args, **kwargs)
  File "C:\Users\Piggy\PycharmProjects\CWA-EA\venv\lib\site-packages\sqlalchemy\orm\session.py", line 943, in commit
    self.transaction.commit()
  File "C:\Users\Piggy\PycharmProjects\CWA-EA\venv\lib\site-packages\sqlalchemy\orm\session.py", line 467, in commit
    self._prepare_impl()
  File "C:\Users\Piggy\PycharmProjects\CWA-EA\venv\lib\site-packages\sqlalchemy\orm\session.py", line 447, in _prepare_impl
    self.session.flush()
  File "C:\Users\Piggy\PycharmProjects\CWA-EA\venv\lib\site-packages\sqlalchemy\orm\session.py", line 2254, in flush
    self._flush(objects)
  File "C:\Users\Piggy\PycharmProjects\CWA-EA\venv\lib\site-packages\sqlalchemy\orm\session.py", line 2380, in _flush
    transaction.rollback(_capture_exception=True)
  File "C:\Users\Piggy\PycharmProjects\CWA-EA\venv\lib\site-packages\sqlalchemy\util\langhelpers.py", line 66, in __exit__
    compat.reraise(exc_type, exc_value, exc_tb)
  File "C:\Users\Piggy\PycharmProjects\CWA-EA\venv\lib\site-packages\sqlalchemy\util\compat.py", line 187, in reraise
    raise value
  File "C:\Users\Piggy\PycharmProjects\CWA-EA\venv\lib\site-packages\sqlalchemy\orm\session.py", line 2344, in _flush
    flush_context.execute()
  File "C:\Users\Piggy\PycharmProjects\CWA-EA\venv\lib\site-packages\sqlalchemy\orm\unitofwork.py", line 391, in execute
    rec.execute(self)
  File "C:\Users\Piggy\PycharmProjects\CWA-EA\venv\lib\site-packages\sqlalchemy\orm\unitofwork.py", line 556, in execute
    uow
  File "C:\Users\Piggy\PycharmProjects\CWA-EA\venv\lib\site-packages\sqlalchemy\orm\persistence.py", line 181, in save_obj
    mapper, table, insert)
  File "C:\Users\Piggy\PycharmProjects\CWA-EA\venv\lib\site-packages\sqlalchemy\orm\persistence.py", line 830, in _emit_insert_statements
    execute(statement, multiparams)
  File "C:\Users\Piggy\PycharmProjects\CWA-EA\venv\lib\site-packages\sqlalchemy\engine\base.py", line 948, in execute
    return meth(self, multiparams, params)
  File "C:\Users\Piggy\PycharmProjects\CWA-EA\venv\lib\site-packages\sqlalchemy\sql\elements.py", line 269, in _execute_on_connection
    return connection._execute_clauseelement(self, multiparams, params)
  File "C:\Users\Piggy\PycharmProjects\CWA-EA\venv\lib\site-packages\sqlalchemy\engine\base.py", line 1060, in _execute_clauseelement
    compiled_sql, distilled_params
  File "C:\Users\Piggy\PycharmProjects\CWA-EA\venv\lib\site-packages\sqlalchemy\engine\base.py", line 1200, in _execute_context
    context)
  File "C:\Users\Piggy\PycharmProjects\CWA-EA\venv\lib\site-packages\sqlalchemy\engine\base.py", line 1413, in _handle_dbapi_exception
    exc_info
  File "C:\Users\Piggy\PycharmProjects\CWA-EA\venv\lib\site-packages\sqlalchemy\util\compat.py", line 203, in raise_from_cause
    reraise(type(exception), exception, tb=exc_tb, cause=cause)
  File "C:\Users\Piggy\PycharmProjects\CWA-EA\venv\lib\site-packages\sqlalchemy\util\compat.py", line 186, in reraise
    raise value.with_traceback(tb)
  File "C:\Users\Piggy\PycharmProjects\CWA-EA\venv\lib\site-packages\sqlalchemy\engine\base.py", line 1193, in _execute_context
    context)
  File "C:\Users\Piggy\PycharmProjects\CWA-EA\venv\lib\site-packages\sqlalchemy\engine\default.py", line 508, in do_execute
    cursor.execute(statement, parameters)
sqlalchemy.exc.IntegrityError: (sqlite3.IntegrityError) datatype mismatch [SQL: 'INSERT INTO newtopic (pid, topic, timestamp, tag, user_id, post) VALUES (?, ?, ?, ?, ?, ?)'] [parameters: ('', 'lkj', '2021-04-28 09:14:30.965528', '1', '', 'fds')] (Background on this error at: http://sqlalche.me/e/gkpj)
2021-04-28 17:30:07,571 INFO: Microblog startup [in C:\Users\Piggy\PycharmProjects\CWA-EA\app\__init__.py:74]
2021-04-28 17:30:26,160 INFO: Microblog startup [in C:\Users\Piggy\PycharmProjects\CWA-EA\app\__init__.py:74]
2021-04-28 17:30:30,748 ERROR: Exception on /new_topic [POST] [in C:\Users\Piggy\PycharmProjects\CWA-EA\venv\lib\site-packages\flask\app.py:1761]
Traceback (most recent call last):
  File "C:\Users\Piggy\PycharmProjects\CWA-EA\venv\lib\site-packages\flask\app.py", line 2292, in wsgi_app
    response = self.full_dispatch_request()
  File "C:\Users\Piggy\PycharmProjects\CWA-EA\venv\lib\site-packages\flask\app.py", line 1815, in full_dispatch_request
    rv = self.handle_user_exception(e)
  File "C:\Users\Piggy\PycharmProjects\CWA-EA\venv\lib\site-packages\flask\app.py", line 1718, in handle_user_exception
    reraise(exc_type, exc_value, tb)
  File "C:\Users\Piggy\PycharmProjects\CWA-EA\venv\lib\site-packages\flask\_compat.py", line 35, in reraise
    raise value
  File "C:\Users\Piggy\PycharmProjects\CWA-EA\venv\lib\site-packages\flask\app.py", line 1813, in full_dispatch_request
    rv = self.dispatch_request()
  File "C:\Users\Piggy\PycharmProjects\CWA-EA\venv\lib\site-packages\flask\app.py", line 1799, in dispatch_request
    return self.view_functions[rule.endpoint](**req.view_args)
  File "C:\Users\Piggy\PycharmProjects\CWA-EA\app\main\routes.py", line 99, in new_topic
    user_id=form.user_id.data)
TypeError: __init__() got an unexpected keyword argument 'user_id'
2021-04-28 17:37:07,737 INFO: Microblog startup [in C:\Users\Piggy\PycharmProjects\CWA-EA\app\__init__.py:74]
2021-04-28 17:37:37,204 INFO: Microblog startup [in C:\Users\Piggy\PycharmProjects\CWA-EA\app\__init__.py:74]
